<section id="numpy-exceptions-axiserror"> <h1>numpy.exceptions.AxisError</h1> <dl class="py exception"> <dt class="sig sig-object py" id="numpy.exceptions.AxisError"> <em class="property">exception</em><span class="sig-prename descclassname">exceptions.</span><span class="sig-name descname">AxisError</span><span class="sig-paren">(</span><em class="sig-param"><span class="n">axis</span></em>, <em class="sig-param"><span class="n">ndim</span><span class="o">=</span><span class="default_value">None</span></em>, <em class="sig-param"><span class="n">msg_prefix</span><span class="o">=</span><span class="default_value">None</span></em><span class="sig-paren">)</span><a class="reference external" href="https://github.com/numpy/numpy/blob/v2.0.0/numpy/exceptions.py#L109-L198"><span class="viewcode-link">[source]</span></a>
</dt> <dd>
<p>Axis supplied was invalid.</p> <p>This is raised whenever an <code>axis</code> parameter is specified that is larger than the number of array dimensions. For compatibility with code written against older numpy versions, which raised a mixture of <a class="reference external" href="https://docs.python.org/3/library/exceptions.html#ValueError" title="(in Python v3.12)"><code>ValueError</code></a> and <a class="reference external" href="https://docs.python.org/3/library/exceptions.html#IndexError" title="(in Python v3.12)"><code>IndexError</code></a> for this situation, this exception subclasses both to ensure that <code>except ValueError</code> and <code>except IndexError</code> statements continue to catch <code>AxisError</code>.</p> <div class="versionadded"> <p><span class="versionmodified added">New in version 1.13.</span></p> </div> <dl class="field-list simple"> <dt class="field-odd">Parameters<span class="colon">:</span>
</dt> <dd class="field-odd">
<dl class="simple"> <dt>
<strong>axis</strong><span class="classifier">int or str</span>
</dt>
<dd>
<p>The out of bounds axis or a custom exception message. If an axis is provided, then <a class="reference internal" href="numpy.ndim.html#numpy.ndim" title="numpy.ndim"><code>ndim</code></a> should be specified as well.</p> </dd> <dt>
<strong>ndim</strong><span class="classifier">int, optional</span>
</dt>
<dd>
<p>The number of array dimensions.</p> </dd> <dt>
<strong>msg_prefix</strong><span class="classifier">str, optional</span>
</dt>
<dd>
<p>A prefix for the exception message.</p> </dd> </dl> </dd> </dl> <h4 class="rubric">Examples</h4> <pre data-language="python">&gt;&gt;&gt; array_1d = np.arange(10)
&gt;&gt;&gt; np.cumsum(array_1d, axis=1)
Traceback (most recent call last):
  ...
numpy.exceptions.AxisError: axis 1 is out of bounds for array of dimension 1
</pre> <p>Negative axes are preserved:</p> <pre data-language="python">&gt;&gt;&gt; np.cumsum(array_1d, axis=-2)
Traceback (most recent call last):
  ...
numpy.exceptions.AxisError: axis -2 is out of bounds for array of dimension 1
</pre> <p>The class constructor generally takes the axis and arraysâ€™ dimensionality as arguments:</p> <pre data-language="python">&gt;&gt;&gt; print(np.exceptions.AxisError(2, 1, msg_prefix='error'))
error: axis 2 is out of bounds for array of dimension 1
</pre> <p>Alternatively, a custom exception message can be passed:</p> <pre data-language="python">&gt;&gt;&gt; print(np.exceptions.AxisError('Custom error message'))
Custom error message
</pre> <dl class="field-list"> <dt class="field-odd">Attributes<span class="colon">:</span>
</dt> <dd class="field-odd">
<dl> <dt>
<strong>axis</strong><span class="classifier">int, optional</span>
</dt>
<dd>
<p>The out of bounds axis or <code>None</code> if a custom exception message was provided. This should be the axis as passed by the user, before any normalization to resolve negative indices.</p> <div class="versionadded"> <p><span class="versionmodified added">New in version 1.22.</span></p> </div> </dd> <dt>
<strong>ndim</strong><span class="classifier">int, optional</span>
</dt>
<dd>
<p>The number of array dimensions or <code>None</code> if a custom exception message was provided.</p> <div class="versionadded"> <p><span class="versionmodified added">New in version 1.22.</span></p> </div> </dd> </dl> </dd> </dl> </dd>
</dl> </section><div class="_attribution">
  <p class="_attribution-p">
    &copy; 2005&ndash;2024 NumPy Developers<br>Licensed under the 3-clause BSD License.<br>
    <a href="https://numpy.org/doc/2.0/reference/generated/numpy.exceptions.AxisError.html" class="_attribution-link">https://numpy.org/doc/2.0/reference/generated/numpy.exceptions.AxisError.html</a>
  </p>
</div>
