<div class="getting-started-title"> <small>Getting Started</small> <h1>try, catch, and rescue</h1> </div>  <p>Elixir has three error mechanisms: errors, throws, and exits. In this chapter, we will explore each of them and include remarks about when each should be used.</p> <h2 id="errors">Errors</h2> <p>Errors (or <em>exceptions</em>) are used when exceptional things happen in the code. A sample error can be retrieved by trying to add a number to an atom:</p> <div class="language-elixir highlighter-rouge"><pre class="highlight" data-language="">iex&gt; :foo + 1
** (ArithmeticError) bad argument in arithmetic expression
     :erlang.+(:foo, 1)
</pre></div> <p>A runtime error can be raised any time by using <code class="language-plaintext highlighter-rouge">raise/1</code>:</p> <div class="language-elixir highlighter-rouge"><pre class="highlight" data-language="">iex&gt; raise "oops"
** (RuntimeError) oops
</pre></div> <p>Other errors can be raised with <code class="language-plaintext highlighter-rouge">raise/2</code> passing the error name and a list of keyword arguments:</p> <div class="language-elixir highlighter-rouge"><pre class="highlight" data-language="">iex&gt; raise ArgumentError, message: "invalid argument foo"
** (ArgumentError) invalid argument foo
</pre></div> <p>You can also define your own errors by creating a module and using the <code class="language-plaintext highlighter-rouge">defexception</code> construct inside it. This way, you’ll create an error with the same name as the module it’s defined in. The most common case is to define a custom exception with a message field:</p> <div class="language-elixir highlighter-rouge"><pre class="highlight" data-language="">iex&gt; defmodule MyError do
iex&gt;   defexception message: "default message"
iex&gt; end
iex&gt; raise MyError
** (MyError) default message
iex&gt; raise MyError, message: "custom message"
** (MyError) custom message
</pre></div> <p>Errors can be <strong>rescued</strong> using the <code class="language-plaintext highlighter-rouge">try/rescue</code> construct:</p> <div class="language-elixir highlighter-rouge"><pre class="highlight" data-language="">iex&gt; try do
...&gt;   raise "oops"
...&gt; rescue
...&gt;   e in RuntimeError -&gt; e
...&gt; end
%RuntimeError{message: "oops"}
</pre></div> <p>The example above rescues the runtime error and returns the exception itself, which is then printed in the <code class="language-plaintext highlighter-rouge">iex</code> session.</p> <p>If you don’t have any use for the exception, you don’t have to pass a variable to <code class="language-plaintext highlighter-rouge">rescue</code>:</p> <div class="language-elixir highlighter-rouge"><pre class="highlight" data-language="">iex&gt; try do
...&gt;   raise "oops"
...&gt; rescue
...&gt;   RuntimeError -&gt; "Error!"
...&gt; end
"Error!"
</pre></div> <p>In practice, Elixir developers rarely use the <code class="language-plaintext highlighter-rouge">try/rescue</code> construct. For example, many languages would force you to rescue an error when a file cannot be opened successfully. Elixir instead provides a <code class="language-plaintext highlighter-rouge">File.read/1</code> function which returns a tuple containing information about whether the file was opened successfully:</p> <div class="language-elixir highlighter-rouge"><pre class="highlight" data-language="">iex&gt; File.read("hello")
{:error, :enoent}
iex&gt; File.write("hello", "world")
:ok
iex&gt; File.read("hello")
{:ok, "world"}
</pre></div> <p>There is no <code class="language-plaintext highlighter-rouge">try/rescue</code> here. In case you want to handle multiple outcomes of opening a file, you can use pattern matching using the <code class="language-plaintext highlighter-rouge">case</code> construct:</p> <div class="language-elixir highlighter-rouge"><pre class="highlight" data-language="">iex&gt; case File.read("hello") do
...&gt;   {:ok, body} -&gt; IO.puts("Success: #{body}")
...&gt;   {:error, reason} -&gt; IO.puts("Error: #{reason}")
...&gt; end
</pre></div> <p>For the cases where you do expect a file to exist (and the lack of that file is truly an <em>error</em>) you may use <code class="language-plaintext highlighter-rouge">File.read!/1</code>:</p> <div class="language-elixir highlighter-rouge"><pre class="highlight" data-language="">iex&gt; File.read!("unknown")
** (File.Error) could not read file "unknown": no such file or directory
    (elixir) lib/file.ex:272: File.read!/1
</pre></div> <p>At the end of the day, it’s up to your application to decide if an error while opening a file is exceptional or not. That’s why Elixir doesn’t impose exceptions on <code class="language-plaintext highlighter-rouge">File.read/1</code> and many other functions. Instead, it leaves it up to the developer to choose the best way to proceed.</p> <p>Many functions in the standard library follow the pattern of having a counterpart that raises an exception instead of returning tuples to match against. The convention is to create a function (<code class="language-plaintext highlighter-rouge">foo</code>) which returns <code class="language-plaintext highlighter-rouge">{:ok, result}</code> or <code class="language-plaintext highlighter-rouge">{:error, reason}</code> tuples and another function (<code class="language-plaintext highlighter-rouge">foo!</code>, same name but with a trailing <code class="language-plaintext highlighter-rouge">!</code>) that takes the same arguments as <code class="language-plaintext highlighter-rouge">foo</code> but which raises an exception if there’s an error. <code class="language-plaintext highlighter-rouge">foo!</code> should return the result (not wrapped in a tuple) if everything goes fine. The <a href="https://hexdocs.pm/elixir/File.html"><code class="language-plaintext highlighter-rouge">File</code> module</a> is a good example of this convention.</p> <h3 id="fail-fast--let-it-crash">Fail fast / Let it crash</h3> <p>One saying that is common in the Erlang community, as well as Elixir’s, is “fail fast” / “let it crash”. The idea behind let it crash is that, in case something <em>unexpected</em> happens, it is best to let the exception happen, without rescuing it.</p> <p>It is important to emphasize the word <em>unexpected</em>. For example, imagine you are building a script to process files. Your script receives filenames as inputs. It is expected that users may make mistakes and provide unknown filenames. In this scenario, while you could use <code class="language-plaintext highlighter-rouge">File.read!/1</code> to read files and let it crash in case of invalid filenames, it probably makes more sense to use <code class="language-plaintext highlighter-rouge">File.read/1</code> and provide users of your script with a clear and precise feedback of what went wrong.</p> <p>Other times, you may fully expect a certain file to exist, and in case it does not, it means something terribly wrong has happened elsewhere. In such cases, <code class="language-plaintext highlighter-rouge">File.read!/1</code> is all you need.</p> <p>The second approach also works because, as discussed in the <a href="processes.html">Processes</a> chapter, all Elixir code runs inside processes that are isolated and don’t share anything by default. Therefore, an unhandled exception in a process will never crash or corrupt the state of another process. This allows us to define supervisor processes, which are meant to observe when a process terminates unexpectedly, and start a new one in its place.</p> <p>At the end of the day, “fail fast” / “let it crash” is a way of saying that, when something <em>unexpected</em> happens, it is best to start from scratch within a new process, freshly started by a supervisor, rather than blindly trying to rescue all possible error cases without the full context of when and how they can happen.</p> <h3 id="reraise">Reraise</h3> <p>While we generally avoid using <code class="language-plaintext highlighter-rouge">try/rescue</code> in Elixir, one situation where we may want to use such constructs is for observability/monitoring. Imagine you want to log that something went wrong, you could do:</p> <div class="language-elixir highlighter-rouge"><pre class="highlight" data-language="">try do
  ... some code ...
rescue
  e -&gt;
    Logger.error(Exception.format(:error, e, __STACKTRACE__))
    reraise e, __STACKTRACE__
end
</pre></div> <p>In the example above, we rescued the exception, logged it, and then re-raised it. We use the <code class="language-plaintext highlighter-rouge">__STACKTRACE__</code> construct both when formatting the exception and when re-raising. This ensures we reraise the exception as is, without changing value or its origin.</p> <p>Generally speaking, we take errors in Elixir literally: they are reserved for unexpected and/or exceptional situations, never for controlling the flow of our code. In case you actually need flow control constructs, <em>throws</em> should be used. That’s what we are going to see next.</p> <h2 id="throws">Throws</h2> <p>In Elixir, a value can be thrown and later be caught. <code class="language-plaintext highlighter-rouge">throw</code> and <code class="language-plaintext highlighter-rouge">catch</code> are reserved for situations where it is not possible to retrieve a value unless by using <code class="language-plaintext highlighter-rouge">throw</code> and <code class="language-plaintext highlighter-rouge">catch</code>.</p> <p>Those situations are quite uncommon in practice except when interfacing with libraries that do not provide a proper API. For example, let’s imagine the <code class="language-plaintext highlighter-rouge">Enum</code> module did not provide any API for finding a value and that we needed to find the first multiple of 13 in a list of numbers:</p> <div class="language-elixir highlighter-rouge"><pre class="highlight" data-language="">iex&gt; try do
...&gt;   Enum.each(-50..50, fn x -&gt;
...&gt;     if rem(x, 13) == 0, do: throw(x)
...&gt;   end)
...&gt;   "Got nothing"
...&gt; catch
...&gt;   x -&gt; "Got #{x}"
...&gt; end
"Got -39"
</pre></div> <p>Since <code class="language-plaintext highlighter-rouge">Enum</code> <em>does</em> provide a proper API, in practice <code class="language-plaintext highlighter-rouge">Enum.find/2</code> is the way to go:</p> <div class="language-elixir highlighter-rouge"><pre class="highlight" data-language="">iex&gt; Enum.find(-50..50, &amp;(rem(&amp;1, 13) == 0))
-39
</pre></div> <h2 id="exits">Exits</h2> <p>All Elixir code runs inside processes that communicate with each other. When a process dies of “natural causes” (e.g., unhandled exceptions), it sends an <code class="language-plaintext highlighter-rouge">exit</code> signal. A process can also die by explicitly sending an <code class="language-plaintext highlighter-rouge">exit</code> signal:</p> <div class="language-elixir highlighter-rouge"><pre class="highlight" data-language="">iex&gt; spawn_link(fn -&gt; exit(1) end)
** (EXIT from #PID&lt;0.56.0&gt;) shell process exited with reason: 1
</pre></div> <p>In the example above, the linked process died by sending an <code class="language-plaintext highlighter-rouge">exit</code> signal with a value of 1. The Elixir shell automatically handles those messages and prints them to the terminal.</p> <p><code class="language-plaintext highlighter-rouge">exit</code> can also be “caught” using <code class="language-plaintext highlighter-rouge">try/catch</code>:</p> <div class="language-elixir highlighter-rouge"><pre class="highlight" data-language="">iex&gt; try do
...&gt;   exit("I am exiting")
...&gt; catch
...&gt;   :exit, _ -&gt; "not really"
...&gt; end
"not really"
</pre></div> <p>Using <code class="language-plaintext highlighter-rouge">try/catch</code> is already uncommon and using it to catch exits is even rarer.</p> <p><code class="language-plaintext highlighter-rouge">exit</code> signals are an important part of the fault tolerant system provided by the Erlang <abbr title="Virtual Machine">VM</abbr>. Processes usually run under supervision trees which are themselves processes that listen to <code class="language-plaintext highlighter-rouge">exit</code> signals from the supervised processes. Once an <code class="language-plaintext highlighter-rouge">exit</code> signal is received, the supervision strategy kicks in and the supervised process is restarted.</p> <p>It is exactly this supervision system that makes constructs like <code class="language-plaintext highlighter-rouge">try/catch</code> and <code class="language-plaintext highlighter-rouge">try/rescue</code> so uncommon in Elixir. Instead of rescuing an error, we’d rather “fail fast” since the supervision tree will guarantee our application will go back to a known initial state after the error.</p> <h2 id="after">After</h2> <p>Sometimes it’s necessary to ensure that a resource is cleaned up after some action that could potentially raise an error. The <code class="language-plaintext highlighter-rouge">try/after</code> construct allows you to do that. For example, we can open a file and use an <code class="language-plaintext highlighter-rouge">after</code> clause to close it – even if something goes wrong:</p> <div class="language-elixir highlighter-rouge"><pre class="highlight" data-language="">iex&gt; {:ok, file} = File.open("sample", [:utf8, :write])
iex&gt; try do
...&gt;   IO.write(file, "olá")
...&gt;   raise "oops, something went wrong"
...&gt; after
...&gt;   File.close(file)
...&gt; end
** (RuntimeError) oops, something went wrong
</pre></div> <p>The <code class="language-plaintext highlighter-rouge">after</code> clause will be executed regardless of whether or not the tried block succeeds. Note, however, that if a linked process exits, this process will exit and the <code class="language-plaintext highlighter-rouge">after</code> clause will not get run. Thus <code class="language-plaintext highlighter-rouge">after</code> provides only a soft guarantee. Luckily, files in Elixir are also linked to the current processes and therefore they will always get closed if the current process crashes, independent of the <code class="language-plaintext highlighter-rouge">after</code> clause. You will find the same to be true for other resources like ETS tables, sockets, ports and more.</p> <p>Sometimes you may want to wrap the entire body of a function in a <code class="language-plaintext highlighter-rouge">try</code> construct, often to guarantee some code will be executed afterwards. In such cases, Elixir allows you to omit the <code class="language-plaintext highlighter-rouge">try</code> line:</p> <div class="language-elixir highlighter-rouge"><pre class="highlight" data-language="">iex&gt; defmodule RunAfter do
...&gt;   def without_even_trying do
...&gt;     raise "oops"
...&gt;   after
...&gt;     IO.puts "cleaning up!"
...&gt;   end
...&gt; end
iex&gt; RunAfter.without_even_trying
cleaning up!
** (RuntimeError) oops
</pre></div> <p>Elixir will automatically wrap the function body in a <code class="language-plaintext highlighter-rouge">try</code> whenever one of <code class="language-plaintext highlighter-rouge">after</code>, <code class="language-plaintext highlighter-rouge">rescue</code> or <code class="language-plaintext highlighter-rouge">catch</code> is specified.</p> <h2 id="else">Else</h2> <p>If an <code class="language-plaintext highlighter-rouge">else</code> block is present, it will match on the results of the <code class="language-plaintext highlighter-rouge">try</code> block whenever the <code class="language-plaintext highlighter-rouge">try</code> block finishes without a throw or an error.</p> <div class="language-elixir highlighter-rouge"><pre class="highlight" data-language="">iex&gt; x = 2
2
iex&gt; try do
...&gt;   1 / x
...&gt; rescue
...&gt;   ArithmeticError -&gt;
...&gt;     :infinity
...&gt; else
...&gt;   y when y &lt; 1 and y &gt; -1 -&gt;
...&gt;     :small
...&gt;   _ -&gt;
...&gt;     :large
...&gt; end
:small
</pre></div> <p>Exceptions in the <code class="language-plaintext highlighter-rouge">else</code> block are not caught. If no pattern inside the <code class="language-plaintext highlighter-rouge">else</code> block matches, an exception will be raised; this exception is not caught by the current <code class="language-plaintext highlighter-rouge">try/catch/rescue/after</code> block.</p> <h2 id="variables-scope">Variables scope</h2> <p>Similar to <code class="language-plaintext highlighter-rouge">case</code>, <code class="language-plaintext highlighter-rouge">cond</code>, <code class="language-plaintext highlighter-rouge">if</code> and other constructs in Elixir, variables defined inside <code class="language-plaintext highlighter-rouge">try/catch/rescue/after</code> blocks do not leak to the outer context. In other words, this code is invalid:</p> <div class="language-elixir highlighter-rouge"><pre class="highlight" data-language="">iex&gt; try do
...&gt;   raise "fail"
...&gt;   what_happened = :did_not_raise
...&gt; rescue
...&gt;   _ -&gt; what_happened = :rescued
...&gt; end
iex&gt; what_happened
** (CompileError) undefined function: what_happened/0
</pre></div> <p>Instead, you should return the value of the <code class="language-plaintext highlighter-rouge">try</code> expression:</p> <div class="language-elixir highlighter-rouge"><pre class="highlight" data-language="">iex&gt; what_happened =
...&gt;   try do
...&gt;     raise "fail"
...&gt;     :did_not_raise
...&gt;   rescue
...&gt;     _ -&gt; :rescued
...&gt;   end
iex&gt; what_happened
:rescued
</pre></div> <p>Furthermore, variables defined in the do-block of <code class="language-plaintext highlighter-rouge">try</code> are not available inside <code class="language-plaintext highlighter-rouge">rescue/after/else</code> either. This is because the <code class="language-plaintext highlighter-rouge">try</code> block may fail at any moment and therefore the variables may have never been bound in the first place. So this also isn’t valid:</p> <div class="language-elixir highlighter-rouge"><pre class="highlight" data-language="">iex&gt; try do
...&gt;   raise "fail"
...&gt;   another_what_happened = :did_not_raise
...&gt; rescue
...&gt;   _ -&gt; another_what_happened
...&gt; end
** (CompileError) undefined function: another_what_happened/0
</pre></div> <p>This finishes our introduction to <code class="language-plaintext highlighter-rouge">try</code>, <code class="language-plaintext highlighter-rouge">catch</code>, and <code class="language-plaintext highlighter-rouge">rescue</code>. You will find they are used less frequently in Elixir than in other languages.</p><div class="_attribution">
  <p class="_attribution-p">
    &copy; 2012 Plataformatec<br>Licensed under the Apache License, Version 2.0.<br>
    <a href="https://elixir-lang.org/getting-started/try-catch-and-rescue.html" class="_attribution-link">https://elixir-lang.org/getting-started/try-catch-and-rescue.html</a>
  </p>
</div>
