<header><h1>try...catch</h1>
<details class="baseline-indicator high"><summary><div class="status-title">Baseline <span class="not-bold">Widely available</span>
</div>

</summary><div class="extra">
<p>This feature is well established and works across many devices and browser versions. Itâ€™s been available across browsers since July 2015.</p>
<ul>
<li><a href="https://developer.mozilla.org/en-US/docs/Glossary/Baseline/Compatibility" data-glean="baseline_link_learn_more" target="_blank" class="learn-more">Learn more</a></li>
<li><a href="#browser_compatibility" data-glean="baseline_link_bcd_table">See full compatibility</a></li>
<li><a href="https://survey.alchemer.com/s3/7634825/MDN-baseline-feedback?page=%2Fen-US%2Fdocs%2FWeb%2FJavaScript%2FReference%2FStatements%2Ftry...catch&amp;level=high" data-glean="baseline_link_feedback" class="feedback-link" target="_blank" rel="noreferrer">Report feedback</a></li>
</ul>
</div></details></header><div class="section-content"><p>The <code>try...catch</code> statement is comprised of a <code>try</code> block and either a <code>catch</code> block, a <code>finally</code> block, or both. The code in the <code>try</code> block is executed first, and if it throws an exception, the code in the <code>catch</code> block will be executed. The code in the <code>finally</code> block will always be executed before control flow exits the entire construct.</p></div>
<section aria-labelledby="try_it"><h2 id="try_it">Try it</h2>
<div class="section-content"><iframe class="interactive is-js-height" height="200" src="https://interactive-examples.mdn.mozilla.net/pages/js/statement-trycatch.html" title="MDN Web Docs Interactive Example" allow="clipboard-write" loading="lazy"></iframe></div></section><section aria-labelledby="syntax"><h2 id="syntax">Syntax</h2>
<div class="section-content">
<div class="code-example"><pre data-language="js">try {
  tryStatements
} catch (exceptionVar) {
  catchStatements
} finally {
  finallyStatements
}
</pre></div> <dl> <dt id="trystatements"><a href="#trystatements"><code>tryStatements</code></a></dt> <dd> <p>The statements to be executed.</p> </dd> <dt id="catchstatements"><a href="#catchstatements"><code>catchStatements</code></a></dt> <dd> <p>Statement that is executed if an exception is thrown in the <code>try</code> block.</p> </dd> <dt id="exceptionvar"><a href="#exceptionvar"><code>exceptionVar</code> <span class="badge inline optional">Optional</span></a></dt> <dd> <p>An optional <a href="#catch_binding">identifier or pattern</a> to hold the caught exception for the associated <code>catch</code> block. If the <code>catch</code> block does not use the exception's value, you can omit the <code>exceptionVar</code> and its surrounding parentheses.</p> </dd> <dt id="finallystatements"><a href="#finallystatements"><code>finallyStatements</code></a></dt> <dd> <p>Statements that are executed before control flow exits the <code>try...catch...finally</code> construct. These statements execute regardless of whether an exception was thrown or caught.</p> </dd> </dl>
</div></section><section aria-labelledby="description"><h2 id="description">Description</h2>
<div class="section-content">
<p>The <code>try</code> statement always starts with a <code>try</code> block. Then, a <code>catch</code> block or a <code>finally</code> block must be present. It's also possible to have both <code>catch</code> and <code>finally</code> blocks. This gives us three forms for the <code>try</code> statement:</p> <ul> <li><code>try...catch</code></li> <li><code>try...finally</code></li> <li><code>try...catch...finally</code></li> </ul> <p>Unlike other constructs such as <a href="if...else.html"><code>if</code></a> or <a href="for.html"><code>for</code></a>, the <code>try</code>, <code>catch</code>, and <code>finally</code> blocks must be <em>blocks</em>, instead of single statements.</p> <div class="code-example"><pre data-language="js">try doSomething(); // SyntaxError
catch (e) console.log(e);
</pre></div> <p>A <code>catch</code> block contains statements that specify what to do if an exception is thrown in the <code>try</code> block. If any statement within the <code>try</code> block (or in a function called from within the <code>try</code> block) throws an exception, control is immediately shifted to the <code>catch</code> block. If no exception is thrown in the <code>try</code> block, the <code>catch</code> block is skipped.</p> <p>The <code>finally</code> block will always execute before control flow exits the <code>try...catch...finally</code> construct. It always executes, regardless of whether an exception was thrown or caught.</p> <p>You can nest one or more <code>try</code> statements. If an inner <code>try</code> statement does not have a <code>catch</code> block, the enclosing <code>try</code> statement's <code>catch</code> block is used instead.</p> <p>You can also use the <code>try</code> statement to handle JavaScript exceptions. See the <a href="https://developer.mozilla.org/en-US/docs/Web/JavaScript/Guide/Control_flow_and_error_handling#exception_handling_statements">JavaScript Guide</a> for more information on JavaScript exceptions.</p>
</div></section><section aria-labelledby="catch_binding"><h3 id="catch_binding">Catch binding</h3>
<div class="section-content">
<p>When an exception is thrown in the <code>try</code> block, <code>exceptionVar</code> (i.e., the <code>e</code> in <code>catch (e)</code>) holds the exception value. You can use this <a href="https://developer.mozilla.org/en-US/docs/Glossary/Binding">binding</a> to get information about the exception that was thrown. This <a href="https://developer.mozilla.org/en-US/docs/Glossary/Binding">binding</a> is only available in the <code>catch</code> block's <a href="https://developer.mozilla.org/en-US/docs/Glossary/Scope">scope</a>.</p> <p>It doesn't need to be a single identifier. You can use a <a href="../operators/destructuring_assignment.html">destructuring pattern</a> to assign multiple identifiers at once.</p> <div class="code-example"><pre data-language="js">try {
  throw new TypeError("oops");
} catch ({ name, message }) {
  console.log(name); // "TypeError"
  console.log(message); // "oops"
}
</pre></div> <p>The bindings created by the <code>catch</code> clause live in the same scope as the <code>catch</code> block, so any variables declared in the <code>catch</code> block cannot have the same name as the bindings created by the <code>catch</code> clause. (There's <a href="https://developer.mozilla.org/en-US/docs/Web/JavaScript/Reference/Deprecated_and_obsolete_features#statements">one exception to this rule</a>, but it's a deprecated syntax.)</p> <div class="code-example"><pre data-language="js">try {
  throw new TypeError("oops");
} catch ({ name, message }) {
  var name; // SyntaxError: Identifier 'name' has already been declared
  let message; // SyntaxError: Identifier 'message' has already been declared
}
</pre></div> <p>The exception binding is writable. For example, you may want to normalize the exception value to make sure it's an <a href="../global_objects/error.html"><code>Error</code></a> object.</p> <div class="code-example"><pre data-language="js">try {
  throw "Oops; this is not an Error object";
} catch (e) {
  if (!(e instanceof Error)) {
    e = new Error(e);
  }
  console.error(e.message);
}
</pre></div> <p>If you don't need the exception value, you can omit it along with the enclosing parentheses.</p> <div class="code-example"><pre data-language="js">function isValidJSON(text) {
  try {
    JSON.parse(text);
    return true;
  } catch {
    return false;
  }
}
</pre></div>
</div></section><section aria-labelledby="the_finally_block"><h3 id="the_finally_block">The finally block</h3>
<div class="section-content">
<p>The <code>finally</code> block contains statements to execute after the <code>try</code> block and <code>catch</code> block(s) execute, but before the statements following the <code>try...catch...finally</code> block. Control flow will always enter the <code>finally</code> block, which can proceed in one of the following ways:</p> <ul> <li>Immediately after the <code>try</code> block finishes execution normally (and no exceptions were thrown);</li> <li>Immediately after the <code>catch</code> block finishes execution normally;</li> <li>Immediately before the execution of a control-flow statement (<code>return</code>, <code>throw</code>, <code>break</code>, <code>continue</code>) in the <code>try</code> block or <code>catch</code> block that would exit the block.</li> </ul> <p>If an exception is thrown from the <code>try</code> block, even when there's no <code>catch</code> block to handle the exception, the <code>finally</code> block still executes, in which case the exception is still thrown immediately after the <code>finally</code> block finishes executing.</p> <p>The following example shows one use case for the <code>finally</code> block. The code opens a file and then executes statements that use the file; the <code>finally</code> block makes sure the file always closes after it is used even if an exception was thrown.</p> <div class="code-example"><pre data-language="js">openMyFile();
try {
  // tie up a resource
  writeMyFile(theData);
} finally {
  closeMyFile(); // always close the resource
}
</pre></div> <p>Control flow statements (<code>return</code>, <code>throw</code>, <code>break</code>, <code>continue</code>) in the <code>finally</code> block will "mask" any completion value of the <code>try</code> block or <code>catch</code> block. In this example, the <code>try</code> block tries to return 1, but before returning, the control flow is yielded to the <code>finally</code> block first, so the <code>finally</code> block's return value is returned instead.</p> <div class="code-example"><pre data-language="js">function doIt() {
  try {
    return 1;
  } finally {
    return 2;
  }
}

doIt(); // returns 2
</pre></div> <p>It is generally a bad idea to have control flow statements in the <code>finally</code> block. Only use it for cleanup code.</p>
</div></section><section aria-labelledby="examples"><h2 id="examples">Examples</h2>
</section><section aria-labelledby="unconditional_catch_block"><h3 id="unconditional_catch_block">Unconditional catch block</h3>
<div class="section-content">
<p>When a <code>catch</code> block is used, the <code>catch</code> block is executed when any exception is thrown from within the <code>try</code> block. For example, when the exception occurs in the following code, control transfers to the <code>catch</code> block.</p> <div class="code-example"><pre data-language="js">try {
  throw "myException"; // generates an exception
} catch (e) {
  // statements to handle any exceptions
  logMyErrors(e); // pass exception object to error handler
}
</pre></div> <p>The <code>catch</code> block specifies an identifier (<code>e</code> in the example above) that holds the value of the exception; this value is only available in the <a href="https://developer.mozilla.org/en-US/docs/Glossary/Scope">scope</a> of the <code>catch</code> block.</p>
</div></section><section aria-labelledby="conditional_catch_blocks"><h3 id="conditional_catch_blocks">Conditional catch blocks</h3>
<div class="section-content">
<p>You can create "Conditional <code>catch</code> blocks" by combining <code>try...catch</code> blocks with <code>if...else if...else</code> structures, like this:</p> <div class="code-example"><pre data-language="js">try {
  myRoutine(); // may throw three types of exceptions
} catch (e) {
  if (e instanceof TypeError) {
    // statements to handle TypeError exceptions
  } else if (e instanceof RangeError) {
    // statements to handle RangeError exceptions
  } else if (e instanceof EvalError) {
    // statements to handle EvalError exceptions
  } else {
    // statements to handle any unspecified exceptions
    logMyErrors(e); // pass exception object to error handler
  }
}
</pre></div> <p>A common use case for this is to only catch (and silence) a small subset of expected errors, and then re-throw the error in other cases:</p> <div class="code-example"><pre data-language="js">try {
  myRoutine();
} catch (e) {
  if (e instanceof RangeError) {
    // statements to handle this very common expected error
  } else {
    throw e; // re-throw the error unchanged
  }
}
</pre></div> <p>This may mimic the syntax from other languages, like Java:</p> <div class="code-example"><pre data-language="java">try {
  myRoutine();
} catch (RangeError e) {
  // statements to handle this very common expected error
}
// Other errors are implicitly re-thrown
</pre></div>
</div></section><section aria-labelledby="nested_try_blocks"><h3 id="nested_try_blocks">Nested try blocks</h3>
<div class="section-content">
<p>First, let's see what happens with this:</p> <div class="code-example"><pre data-language="js">try {
  try {
    throw new Error("oops");
  } finally {
    console.log("finally");
  }
} catch (ex) {
  console.error("outer", ex.message);
}

// Logs:
// "finally"
// "outer" "oops"
</pre></div> <p>Now, if we already caught the exception in the inner <code>try</code> block by adding a <code>catch</code> block:</p> <div class="code-example"><pre data-language="js">try {
  try {
    throw new Error("oops");
  } catch (ex) {
    console.error("inner", ex.message);
  } finally {
    console.log("finally");
  }
} catch (ex) {
  console.error("outer", ex.message);
}

// Logs:
// "inner" "oops"
// "finally"
</pre></div> <p>And now, let's rethrow the error.</p> <div class="code-example"><pre data-language="js">try {
  try {
    throw new Error("oops");
  } catch (ex) {
    console.error("inner", ex.message);
    throw ex;
  } finally {
    console.log("finally");
  }
} catch (ex) {
  console.error("outer", ex.message);
}

// Logs:
// "inner" "oops"
// "finally"
// "outer" "oops"
</pre></div> <p>Any given exception will be caught only once by the nearest enclosing <code>catch</code> block unless it is rethrown. Of course, any new exceptions raised in the "inner" block (because the code in <code>catch</code> block may do something that throws), will be caught by the "outer" block.</p>
</div></section><section aria-labelledby="returning_from_a_finally_block"><h3 id="returning_from_a_finally_block">Returning from a finally block</h3>
<div class="section-content">
<p>If the <code>finally</code> block returns a value, this value becomes the return value of the entire <code>try-catch-finally</code> statement, regardless of any <code>return</code> statements in the <code>try</code> and <code>catch</code> blocks. This includes exceptions thrown inside of the <code>catch</code> block:</p> <div class="code-example"><pre data-language="js">(() =&gt; {
  try {
    try {
      throw new Error("oops");
    } catch (ex) {
      console.error("inner", ex.message);
      throw ex;
    } finally {
      console.log("finally");
      return;
    }
  } catch (ex) {
    console.error("outer", ex.message);
  }
})();

// Logs:
// "inner" "oops"
// "finally"
</pre></div> <p>The outer "oops" is not thrown because of the return in the <code>finally</code> block. The same would apply to any value returned from the <code>catch</code> block.</p>
</div></section><h2 id="specifications">Specifications</h2>
<div class="_table"><table class="standard-table">
<thead><tr><th scope="col">Specification</th></tr></thead>
<tbody><tr><td><a href="https://tc39.es/ecma262/multipage/ecmascript-language-statements-and-declarations.html#sec-try-statement">ECMAScript Language Specification <br><small># sec-try-statement</small></a></td></tr></tbody>
</table></div>
<h2 id="browser_compatibility">Browser compatibility</h2>
<div class="_table"><table>
<thead>
<tr id="bct-browser-type">
<th></th>
<th colspan="5">Desktop</th>
<th colspan="6">Mobile</th>
<th colspan="2">Server</th>
</tr>
<tr id="bct-browsers">
<th></th>
<th>Chrome</th>
<th>Edge</th>
<th>Firefox</th>
<th>Opera</th>
<th>Safari</th>
<th>Chrome Android</th>
<th>Firefox for Android</th>
<th>Opera Android</th>
<th>Safari on IOS</th>
<th>Samsung Internet</th>
<th>WebView Android</th>
<th>Deno</th>
<th>Node.js</th>
</tr>
</thead>
<tbody>
<tr>
<th><code>try...catch</code></th>
<td class="bc-supports-yes">1</td>
<td class="bc-supports-yes">12</td>
<td class="bc-supports-yes">1</td>
<td class="bc-supports-yes">4</td>
<td class="bc-supports-yes">1</td>
<td class="bc-supports-yes">18</td>
<td class="bc-supports-yes">4</td>
<td class="bc-supports-yes">10.1</td>
<td class="bc-supports-yes">1</td>
<td class="bc-supports-yes">1.0</td>
<td class="bc-supports-yes">4.4</td>
<td class="bc-supports-yes">1.0</td>
<td class="bc-supports-yes">0.10.0</td>
</tr>
<tr>
<th><code>optional_catch_binding</code></th>
<td class="bc-supports-yes">66</td>
<td class="bc-supports-yes">79</td>
<td class="bc-supports-yes">58</td>
<td class="bc-supports-yes">53</td>
<td class="bc-supports-yes">11.1</td>
<td class="bc-supports-yes">66</td>
<td class="bc-supports-yes">58</td>
<td class="bc-supports-yes">47</td>
<td class="bc-supports-yes">11.3</td>
<td class="bc-supports-yes">9.0</td>
<td class="bc-supports-yes">66</td>
<td class="bc-supports-yes">1.0</td>
<td class="bc-supports-yes">10.0.0</td>
</tr>
</tbody>
</table></div>
<section aria-labelledby="see_also"><h2 id="see_also">See also</h2>
<div class="section-content"><ul> <li><a href="../global_objects/error.html"><code>Error</code></a></li> <li><a href="throw.html"><code>throw</code></a></li> </ul></div></section><div class="_attribution">
  <p class="_attribution-p">
    &copy; 2005&ndash;2024 MDN contributors.<br>Licensed under the Creative Commons Attribution-ShareAlike License v2.5 or later.<br>
    <a href="https://developer.mozilla.org/en-US/docs/Web/JavaScript/Reference/Statements/try...catch" class="_attribution-link">https://developer.mozilla.org/en-US/docs/Web/JavaScript/Reference/Statements/try...catch</a>
  </p>
</div>
