<h1>pandas.errors.PossibleDataLossError</h1> <dl class="py exception"> <dt class="sig sig-object py" id="pandas.errors.PossibleDataLossError"> <em class="property"><span class="pre">exception</span></em><span class="sig-prename descclassname"><span class="pre">pandas.errors.</span></span><span class="sig-name descname"><span class="pre">PossibleDataLossError</span></span><a class="reference external" href="https://github.com/pandas-dev/pandas/blob/v2.2.2/pandas/errors/__init__.py#L662-L671"><span class="viewcode-link"><span class="pre">[source]</span></span></a>
</dt> <dd>
<p>Exception raised when trying to open a HDFStore file when already opened.</p> <p class="rubric">Examples</p> <div class="doctest highlight-default notranslate">
<div class="highlight"><pre data-language="python">&gt;&gt;&gt; store = pd.HDFStore('my-store', 'a') 
&gt;&gt;&gt; store.open("w") 
... # PossibleDataLossError: Re-opening the file [my-store] with mode [a]...
</pre></div> </div> </dd>
</dl><div class="_attribution">
  <p class="_attribution-p">
    &copy; 2008&ndash;2022, AQR Capital Management, LLC, Lambda Foundry, Inc. and PyData Development Team<br>Licensed under the 3-clause BSD License.<br>
    <a href="https://pandas.pydata.org/pandas-docs/version/2.2.2/reference/api/pandas.errors.PossibleDataLossError.html" class="_attribution-link">https://pandas.pydata.org/pandas-docs/version/2.2.2/reference/api/pandas.errors.PossibleDataLossError.html</a>
  </p>
</div>
