<h1 data-toc="exception-handling" id="exception-handling.md">Coroutine exceptions handling</h1>
<p id="bd8e1f94">This section covers exception handling and cancellation on exceptions. We already know that a cancelled coroutine throws <a href="https://kotlinlang.org/api/kotlinx.coroutines/kotlinx-coroutines-core/kotlinx.coroutines/-cancellation-exception/index.html" id="ff61a172" data-external="true" rel="noopener noreferrer">CancellationException</a> in suspension points and that it is ignored by the coroutines' machinery. Here we look at what happens if an exception is thrown during cancellation or multiple children of the same coroutine throw an exception.</p>
<section class="chapter"><h2 id="exception-propagation" data-toc="exception-propagation">Exception propagation</h2>
<p id="72b9ee23">Coroutine builders come in two flavors: propagating exceptions automatically (<a href="https://kotlinlang.org/api/kotlinx.coroutines/kotlinx-coroutines-core/kotlinx.coroutines/launch.html" id="64434bec" data-external="true" rel="noopener noreferrer">launch</a> and <a href="https://kotlinlang.org/api/kotlinx.coroutines/kotlinx-coroutines-core/kotlinx.coroutines.channels/actor.html" id="2930c0b0" data-external="true" rel="noopener noreferrer">actor</a>) or exposing them to users (<a href="https://kotlinlang.org/api/kotlinx.coroutines/kotlinx-coroutines-core/kotlinx.coroutines/async.html" id="ed14017e" data-external="true" rel="noopener noreferrer">async</a> and <a href="https://kotlinlang.org/api/kotlinx.coroutines/kotlinx-coroutines-core/kotlinx.coroutines.channels/produce.html" id="d8f8b550" data-external="true" rel="noopener noreferrer">produce</a>). When these builders are used to create a <em id="21f71a8a" class="">root</em> coroutine, that is not a <em id="879e02b" class="">child</em> of another coroutine, the former builders treat exceptions as <b id="673dd4c7" class="">uncaught</b> exceptions, similar to Java's <code class="code ">Thread.uncaughtExceptionHandler</code>, while the latter are relying on the user to consume the final exception, for example via <a href="https://kotlinlang.org/api/kotlinx.coroutines/kotlinx-coroutines-core/kotlinx.coroutines/-deferred/await.html" id="ef25477a" data-external="true" rel="noopener noreferrer">await</a> or <a href="https://kotlinlang.org/api/kotlinx.coroutines/kotlinx-coroutines-core/kotlinx.coroutines.channels/-receive-channel/receive.html" id="892ebbd9" data-external="true" rel="noopener noreferrer">receive</a> (<a href="https://kotlinlang.org/api/kotlinx.coroutines/kotlinx-coroutines-core/kotlinx.coroutines.channels/produce.html" id="ddb5f3ce" data-external="true" rel="noopener noreferrer">produce</a> and <a href="https://kotlinlang.org/api/kotlinx.coroutines/kotlinx-coroutines-core/kotlinx.coroutines.channels/-receive-channel/receive.html" id="383bb4e4" data-external="true" rel="noopener noreferrer">receive</a> are covered in <a href="https://github.com/Kotlin/kotlinx.coroutines/blob/master/docs/channels.md" id="98652bc0" data-external="true" rel="noopener noreferrer">Channels</a> section).</p>
<p id="f4695ae3">It can be demonstrated by a simple example that creates root coroutines using the <a href="https://kotlinlang.org/api/kotlinx.coroutines/kotlinx-coroutines-core/kotlinx.coroutines/-global-scope/index.html" id="7979a174" data-external="true" rel="noopener noreferrer">GlobalScope</a>:</p>
<aside data-type="note" class="prompt" data-title="" id="9e032cf"><p id="37ef79f4"><a href="https://kotlinlang.org/api/kotlinx.coroutines/kotlinx-coroutines-core/kotlinx.coroutines/-global-scope/index.html" id="5ed666cc" data-external="true" rel="noopener noreferrer">GlobalScope</a> is a delicate API that can backfire in non-trivial ways. Creating a root coroutine for the whole application is one of the rare legitimate uses for <code class="code ">GlobalScope</code>, so you must explicitly opt-in into using <code class="code ">GlobalScope</code> with <code class="code ">@OptIn(DelicateCoroutinesApi::class)</code>.</p></aside><pre class="code" data-language="kotlin">import kotlinx.coroutines.*

//sampleStart
@OptIn(DelicateCoroutinesApi::class)
fun main() = runBlocking {
    val job = GlobalScope.launch { // root coroutine with launch
        println("Throwing exception from launch")
        throw IndexOutOfBoundsException() // Will be printed to the console by Thread.defaultUncaughtExceptionHandler
    }
    job.join()
    println("Joined failed job")
    val deferred = GlobalScope.async { // root coroutine with async
        println("Throwing exception from async")
        throw ArithmeticException() // Nothing is printed, relying on user to call await
    }
    try {
        deferred.await()
        println("Unreached")
    } catch (e: ArithmeticException) {
        println("Caught ArithmeticException")
    }
}
//sampleEnd
</pre>
<aside data-type="note" class="prompt" data-title="" id="77f77771"><p id="fd176037">You can get the full code <a href="https://github.com/Kotlin/kotlinx.coroutines/blob/master/kotlinx-coroutines-core/jvm/test/guide/example-exceptions-01.kt" id="ea9d8695" data-external="true" rel="noopener noreferrer">here</a>.</p></aside><p id="8ad186d5">The output of this code is (with <a href="https://github.com/Kotlin/kotlinx.coroutines/blob/master/docs/coroutine-context-and-dispatchers.md#debugging-coroutines-and-threads" id="2ba6f5fa" data-external="true" rel="noopener noreferrer">debug</a>):</p>
<pre class="code" data-language="plaintext">Throwing exception from launch
Exception in thread "DefaultDispatcher-worker-2 @coroutine#2" java.lang.IndexOutOfBoundsException
Joined failed job
Throwing exception from async
Caught ArithmeticException
</pre></section><section class="chapter"><h2 id="coroutineexceptionhandler" data-toc="coroutineexceptionhandler">CoroutineExceptionHandler</h2>
<p id="aa4e8abb">It is possible to customize the default behavior of printing <b id="c846be56" class="">uncaught</b> exceptions to the console. <a href="https://kotlinlang.org/api/kotlinx.coroutines/kotlinx-coroutines-core/kotlinx.coroutines/-coroutine-exception-handler/index.html" id="1ec2512c" data-external="true" rel="noopener noreferrer">CoroutineExceptionHandler</a> context element on a <em id="a29bd134" class="">root</em> coroutine can be used as a generic <code class="code ">catch</code> block for this root coroutine and all its children where custom exception handling may take place. It is similar to <a href="https://docs.oracle.com/javase/8/docs/api/java/lang/Thread.html#setUncaughtExceptionHandler(java.lang.Thread.UncaughtExceptionHandler)" id="62fc9540" data-external="true" rel="noopener noreferrer"><code class="code ">Thread.uncaughtExceptionHandler</code></a>. You cannot recover from the exception in the <code class="code ">CoroutineExceptionHandler</code>. The coroutine had already completed with the corresponding exception when the handler is called. Normally, the handler is used to log the exception, show some kind of error message, terminate, and/or restart the application.</p>
<p id="f9bda1bb"><code class="code ">CoroutineExceptionHandler</code> is invoked only on <b id="25e10e05" class="">uncaught</b> exceptions â€” exceptions that were not handled in any other way. In particular, all <em id="59def1aa" class="">children</em> coroutines (coroutines created in the context of another <a href="https://kotlinlang.org/api/kotlinx.coroutines/kotlinx-coroutines-core/kotlinx.coroutines/-job/index.html" id="887b7193" data-external="true" rel="noopener noreferrer">Job</a>) delegate handling of their exceptions to their parent coroutine, which also delegates to the parent, and so on until the root, so the <code class="code ">CoroutineExceptionHandler</code> installed in their context is never used. In addition to that, <a href="https://kotlinlang.org/api/kotlinx.coroutines/kotlinx-coroutines-core/kotlinx.coroutines/async.html" id="8021d478" data-external="true" rel="noopener noreferrer">async</a> builder always catches all exceptions and represents them in the resulting <a href="https://kotlinlang.org/api/kotlinx.coroutines/kotlinx-coroutines-core/kotlinx.coroutines/-deferred/index.html" id="3fc25def" data-external="true" rel="noopener noreferrer">Deferred</a> object, so its <code class="code ">CoroutineExceptionHandler</code> has no effect either.</p>
<aside data-type="note" class="prompt" data-title="" id="79869d6"><p id="d74a9cd1">Coroutines running in supervision scope do not propagate exceptions to their parent and are excluded from this rule. A further <a href="#supervision" id="2a5af9e3">Supervision</a> section of this document gives more details.</p></aside><pre class="code" data-language="kotlin">import kotlinx.coroutines.*

@OptIn(DelicateCoroutinesApi::class)
fun main() = runBlocking {
//sampleStart
    val handler = CoroutineExceptionHandler { _, exception -&gt; 
        println("CoroutineExceptionHandler got $exception") 
    }
    val job = GlobalScope.launch(handler) { // root coroutine, running in GlobalScope
        throw AssertionError()
    }
    val deferred = GlobalScope.async(handler) { // also root, but async instead of launch
        throw ArithmeticException() // Nothing will be printed, relying on user to call deferred.await()
    }
    joinAll(job, deferred)
//sampleEnd    
}
</pre>
<aside data-type="note" class="prompt" data-title="" id="101ae185"><p id="2be8baf0">You can get the full code <a href="https://github.com/Kotlin/kotlinx.coroutines/blob/master/kotlinx-coroutines-core/jvm/test/guide/example-exceptions-02.kt" id="65a89aa5" data-external="true" rel="noopener noreferrer">here</a>.</p></aside><p id="72f0180d">The output of this code is:</p>
<pre class="code" data-language="plaintext">CoroutineExceptionHandler got java.lang.AssertionError
</pre></section><section class="chapter"><h2 id="cancellation-and-exceptions" data-toc="cancellation-and-exceptions">Cancellation and exceptions</h2>
<p id="ae44f658">Cancellation is closely related to exceptions. Coroutines internally use <code class="code ">CancellationException</code> for cancellation, these exceptions are ignored by all handlers, so they should be used only as the source of additional debug information, which can be obtained by <code class="code ">catch</code> block. When a coroutine is cancelled using <a href="https://kotlinlang.org/api/kotlinx.coroutines/kotlinx-coroutines-core/kotlinx.coroutines/cancel.html" id="1ed6c68d" data-external="true" rel="noopener noreferrer">Job.cancel</a>, it terminates, but it does not cancel its parent.</p>
<pre class="code" data-language="kotlin">import kotlinx.coroutines.*

fun main() = runBlocking {
//sampleStart
    val job = launch {
        val child = launch {
            try {
                delay(Long.MAX_VALUE)
            } finally {
                println("Child is cancelled")
            }
        }
        yield()
        println("Cancelling child")
        child.cancel()
        child.join()
        yield()
        println("Parent is not cancelled")
    }
    job.join()
//sampleEnd    
}
</pre>
<aside data-type="note" class="prompt" data-title="" id="a71584bd"><p id="c49f9412">You can get the full code <a href="https://github.com/Kotlin/kotlinx.coroutines/blob/master/kotlinx-coroutines-core/jvm/test/guide/example-exceptions-03.kt" id="d72c498b" data-external="true" rel="noopener noreferrer">here</a>.</p></aside><p id="94b8e7d7">The output of this code is:</p>
<pre class="code" data-language="plaintext">Cancelling child
Child is cancelled
Parent is not cancelled
</pre>
<p id="a434994d">If a coroutine encounters an exception other than <code class="code ">CancellationException</code>, it cancels its parent with that exception. This behaviour cannot be overridden and is used to provide stable coroutines hierarchies for <a href="https://github.com/Kotlin/kotlinx.coroutines/blob/master/docs/composing-suspending-functions.md#structured-concurrency-with-async" id="3a60c450" data-external="true" rel="noopener noreferrer">structured concurrency</a>. <a href="https://kotlinlang.org/api/kotlinx.coroutines/kotlinx-coroutines-core/kotlinx.coroutines/-coroutine-exception-handler/index.html" id="a7e71ba8" data-external="true" rel="noopener noreferrer">CoroutineExceptionHandler</a> implementation is not used for child coroutines.</p>
<aside data-type="note" class="prompt" data-title="" id="1a5430d7"><p id="e06ee410">In these examples, <a href="https://kotlinlang.org/api/kotlinx.coroutines/kotlinx-coroutines-core/kotlinx.coroutines/-coroutine-exception-handler/index.html" id="9a44ad7f" data-external="true" rel="noopener noreferrer">CoroutineExceptionHandler</a> is always installed to a coroutine that is created in <a href="https://kotlinlang.org/api/kotlinx.coroutines/kotlinx-coroutines-core/kotlinx.coroutines/-global-scope/index.html" id="94b17043" data-external="true" rel="noopener noreferrer">GlobalScope</a>. It does not make sense to install an exception handler to a coroutine that is launched in the scope of the main <a href="https://kotlinlang.org/api/kotlinx.coroutines/kotlinx-coroutines-core/kotlinx.coroutines/run-blocking.html" id="e207d5ec" data-external="true" rel="noopener noreferrer">runBlocking</a>, since the main coroutine is going to be always cancelled when its child completes with exception despite the installed handler.</p></aside><p id="de3a2ab9">The original exception is handled by the parent only when all its children terminate, which is demonstrated by the following example.</p>
<pre class="code" data-language="kotlin">import kotlinx.coroutines.*

@OptIn(DelicateCoroutinesApi::class)
fun main() = runBlocking {
//sampleStart
    val handler = CoroutineExceptionHandler { _, exception -&gt; 
        println("CoroutineExceptionHandler got $exception") 
    }
    val job = GlobalScope.launch(handler) {
        launch { // the first child
            try {
                delay(Long.MAX_VALUE)
            } finally {
                withContext(NonCancellable) {
                    println("Children are cancelled, but exception is not handled until all children terminate")
                    delay(100)
                    println("The first child finished its non cancellable block")
                }
            }
        }
        launch { // the second child
            delay(10)
            println("Second child throws an exception")
            throw ArithmeticException()
        }
    }
    job.join()
//sampleEnd 
}
</pre>
<aside data-type="note" class="prompt" data-title="" id="36c1cefd"><p id="da77d208">You can get the full code <a href="https://github.com/Kotlin/kotlinx.coroutines/blob/master/kotlinx-coroutines-core/jvm/test/guide/example-exceptions-04.kt" id="8db7a5de" data-external="true" rel="noopener noreferrer">here</a>.</p></aside><p id="f0175cf4">The output of this code is:</p>
<pre class="code" data-language="plaintext">Second child throws an exception
Children are cancelled, but exception is not handled until all children terminate
The first child finished its non cancellable block
CoroutineExceptionHandler got java.lang.ArithmeticException
</pre></section><section class="chapter"><h2 id="exceptions-aggregation" data-toc="exceptions-aggregation">Exceptions aggregation</h2>
<p id="62a7db75">When multiple children of a coroutine fail with an exception, the general rule is "the first exception wins", so the first exception gets handled. All additional exceptions that happen after the first one are attached to the first exception as suppressed ones.</p>
<pre class="code" data-language="kotlin">import kotlinx.coroutines.*
import java.io.*

@OptIn(DelicateCoroutinesApi::class)
fun main() = runBlocking {
    val handler = CoroutineExceptionHandler { _, exception -&gt;
        println("CoroutineExceptionHandler got $exception with suppressed ${exception.suppressed.contentToString()}")
    }
    val job = GlobalScope.launch(handler) {
        launch {
            try {
                delay(Long.MAX_VALUE) // it gets cancelled when another sibling fails with IOException
            } finally {
                throw ArithmeticException() // the second exception
            }
        }
        launch {
            delay(100)
            throw IOException() // the first exception
        }
        delay(Long.MAX_VALUE)
    }
    job.join()  
}
</pre>
<aside data-type="note" class="prompt" data-title="" id="2f66c676"><p id="76b8def6">You can get the full code <a href="https://github.com/Kotlin/kotlinx.coroutines/blob/master/kotlinx-coroutines-core/jvm/test/guide/example-exceptions-05.kt" id="7d468925" data-external="true" rel="noopener noreferrer">here</a>.</p></aside><aside data-type="note" class="prompt" data-title="" id="f6ba2c0e"><p id="8bdf1fce">Note: This above code will work properly only on JDK7+ that supports <code class="code ">suppressed</code> exceptions</p></aside><p id="a1dfafc1">The output of this code is:</p>
<pre class="code" data-language="plaintext">CoroutineExceptionHandler got java.io.IOException with suppressed [java.lang.ArithmeticException]
</pre>
<aside data-type="note" class="prompt" data-title="" id="5a00c788"><p id="44724cf0">Note that this mechanism currently only works on Java version 1.7+. The JS and Native restrictions are temporary and will be lifted in the future.</p></aside><p id="9d2efc01">Cancellation exceptions are transparent and are unwrapped by default:</p>
<pre class="code" data-language="kotlin">import kotlinx.coroutines.*
import java.io.*

@OptIn(DelicateCoroutinesApi::class)
fun main() = runBlocking {
//sampleStart
    val handler = CoroutineExceptionHandler { _, exception -&gt;
        println("CoroutineExceptionHandler got $exception")
    }
    val job = GlobalScope.launch(handler) {
        val inner = launch { // all this stack of coroutines will get cancelled
            launch {
                launch {
                    throw IOException() // the original exception
                }
            }
        }
        try {
            inner.join()
        } catch (e: CancellationException) {
            println("Rethrowing CancellationException with original cause")
            throw e // cancellation exception is rethrown, yet the original IOException gets to the handler  
        }
    }
    job.join()
//sampleEnd    
}
</pre>
<aside data-type="note" class="prompt" data-title="" id="13543e1b"><p id="95471517">You can get the full code <a href="https://github.com/Kotlin/kotlinx.coroutines/blob/master/kotlinx-coroutines-core/jvm/test/guide/example-exceptions-06.kt" id="b0515e3e" data-external="true" rel="noopener noreferrer">here</a>.</p></aside><p id="7ad263b1">The output of this code is:</p>
<pre class="code" data-language="plaintext">Rethrowing CancellationException with original cause
CoroutineExceptionHandler got java.io.IOException
</pre></section><section class="chapter"><h2 id="supervision" data-toc="supervision">Supervision</h2>
<p id="d4a85bef">As we have studied before, cancellation is a bidirectional relationship propagating through the whole hierarchy of coroutines. Let us take a look at the case when unidirectional cancellation is required.</p>
<p id="43691b44">A good example of such a requirement is a UI component with the job defined in its scope. If any of the UI's child tasks have failed, it is not always necessary to cancel (effectively kill) the whole UI component, but if the UI component is destroyed (and its job is cancelled), then it is necessary to cancel all child jobs as their results are no longer needed.</p>
<p id="8c0ccd40">Another example is a server process that spawns multiple child jobs and needs to <em id="992af8db" class="">supervise</em> their execution, tracking their failures and only restarting the failed ones.</p>
<section class="chapter"><h3 id="supervision-job" data-toc="supervision-job">Supervision job</h3>
<p id="650ca54e">The <a href="https://kotlinlang.org/api/kotlinx.coroutines/kotlinx-coroutines-core/kotlinx.coroutines/-supervisor-job.html" id="1531966d" data-external="true" rel="noopener noreferrer">SupervisorJob</a> can be used for these purposes. It is similar to a regular <a href="https://kotlinlang.org/api/kotlinx.coroutines/kotlinx-coroutines-core/kotlinx.coroutines/-job.html" id="9bde831" data-external="true" rel="noopener noreferrer">Job</a> with the only exception that cancellation is propagated only downwards. This can easily be demonstrated using the following example:</p>
<pre class="code" data-language="kotlin">import kotlinx.coroutines.*

fun main() = runBlocking {
//sampleStart
    val supervisor = SupervisorJob()
    with(CoroutineScope(coroutineContext + supervisor)) {
        // launch the first child -- its exception is ignored for this example (don't do this in practice!)
        val firstChild = launch(CoroutineExceptionHandler { _, _ -&gt;  }) {
            println("The first child is failing")
            throw AssertionError("The first child is cancelled")
        }
        // launch the second child
        val secondChild = launch {
            firstChild.join()
            // Cancellation of the first child is not propagated to the second child
            println("The first child is cancelled: ${firstChild.isCancelled}, but the second one is still active")
            try {
                delay(Long.MAX_VALUE)
            } finally {
                // But cancellation of the supervisor is propagated
                println("The second child is cancelled because the supervisor was cancelled")
            }
        }
        // wait until the first child fails &amp; completes
        firstChild.join()
        println("Cancelling the supervisor")
        supervisor.cancel()
        secondChild.join()
    }
//sampleEnd
}
</pre>
<aside data-type="note" class="prompt" data-title="" id="a42aa117"><p id="433d28ea">You can get the full code <a href="https://github.com/Kotlin/kotlinx.coroutines/blob/master/kotlinx-coroutines-core/jvm/test/guide/example-supervision-01.kt" id="48702345" data-external="true" rel="noopener noreferrer">here</a>.</p></aside><p id="43763483">The output of this code is:</p>
<pre class="code" data-language="plaintext">The first child is failing
The first child is cancelled: true, but the second one is still active
Cancelling the supervisor
The second child is cancelled because the supervisor was cancelled
</pre></section><section class="chapter"><h3 id="supervision-scope" data-toc="supervision-scope">Supervision scope</h3>
<p id="d7689a63">Instead of <a href="https://kotlinlang.org/api/kotlinx.coroutines/kotlinx-coroutines-core/kotlinx.coroutines/coroutine-scope.html" id="5d7fb2f3" data-external="true" rel="noopener noreferrer">coroutineScope</a>, we can use <a href="https://kotlinlang.org/api/kotlinx.coroutines/kotlinx-coroutines-core/kotlinx.coroutines/supervisor-scope.html" id="d8ad8166" data-external="true" rel="noopener noreferrer">supervisorScope</a> for <em id="f3c0a434" class="">scoped</em> concurrency. It propagates the cancellation in one direction only and cancels all its children only if it failed itself. It also waits for all children before completion just like <a href="https://kotlinlang.org/api/kotlinx.coroutines/kotlinx-coroutines-core/kotlinx.coroutines/coroutine-scope.html" id="8bb50ec3" data-external="true" rel="noopener noreferrer">coroutineScope</a> does.</p>
<pre class="code" data-language="kotlin">import kotlin.coroutines.*
import kotlinx.coroutines.*

fun main() = runBlocking {
//sampleStart
    try {
        supervisorScope {
            val child = launch {
                try {
                    println("The child is sleeping")
                    delay(Long.MAX_VALUE)
                } finally {
                    println("The child is cancelled")
                }
            }
            // Give our child a chance to execute and print using yield 
            yield()
            println("Throwing an exception from the scope")
            throw AssertionError()
        }
    } catch(e: AssertionError) {
        println("Caught an assertion error")
    }
//sampleEnd
}
</pre>
<aside data-type="note" class="prompt" data-title="" id="2ac4f37b"><p id="f8e6d841">You can get the full code <a href="https://github.com/Kotlin/kotlinx.coroutines/blob/master/kotlinx-coroutines-core/jvm/test/guide/example-supervision-02.kt" id="17727d4c" data-external="true" rel="noopener noreferrer">here</a>.</p></aside><p id="a742d26f">The output of this code is:</p>
<pre class="code" data-language="plaintext">The child is sleeping
Throwing an exception from the scope
The child is cancelled
Caught an assertion error
</pre>
<section class="chapter"><h4 id="exceptions-in-supervised-coroutines" data-toc="exceptions-in-supervised-coroutines">Exceptions in supervised coroutines</h4>
<p id="34901033">Another crucial difference between regular and supervisor jobs is exception handling. Every child should handle its exceptions by itself via the exception handling mechanism. This difference comes from the fact that child's failure does not propagate to the parent. It means that coroutines launched directly inside the <a href="https://kotlinlang.org/api/kotlinx.coroutines/kotlinx-coroutines-core/kotlinx.coroutines/supervisor-scope.html" id="d4b204f1" data-external="true" rel="noopener noreferrer">supervisorScope</a> <em id="4dacb26a" class="">do</em> use the <a href="https://kotlinlang.org/api/kotlinx.coroutines/kotlinx-coroutines-core/kotlinx.coroutines/-coroutine-exception-handler/index.html" id="a084a0a0" data-external="true" rel="noopener noreferrer">CoroutineExceptionHandler</a> that is installed in their scope in the same way as root coroutines do (see the <a href="#coroutineexceptionhandler" id="b0f938f9">CoroutineExceptionHandler</a> section for details).</p>
<pre class="code" data-language="kotlin">import kotlin.coroutines.*
import kotlinx.coroutines.*

fun main() = runBlocking {
//sampleStart
    val handler = CoroutineExceptionHandler { _, exception -&gt; 
        println("CoroutineExceptionHandler got $exception") 
    }
    supervisorScope {
        val child = launch(handler) {
            println("The child throws an exception")
            throw AssertionError()
        }
        println("The scope is completing")
    }
    println("The scope is completed")
//sampleEnd
}
</pre>
<aside data-type="note" class="prompt" data-title="" id="4df2ff22"><p id="27aaf47a">You can get the full code <a href="https://github.com/Kotlin/kotlinx.coroutines/blob/master/kotlinx-coroutines-core/jvm/test/guide/example-supervision-03.kt" id="fbe873a7" data-external="true" rel="noopener noreferrer">here</a>.</p></aside><p id="f1a0886c">The output of this code is:</p>
<pre class="code" data-language="plaintext">The scope is completing
The child throws an exception
CoroutineExceptionHandler got java.lang.AssertionError
The scope is completed
</pre></section></section></section><div class="last-modified"> Last modified: 25 July 2023</div>

<div class="navigation-links _bottom"> <a class="navigation-links__prev" href="channels.html">Channels</a> <a class="navigation-links__next" href="shared-mutable-state-and-concurrency.html">Shared mutable state and concurrency</a> </div><div class="_attribution">
  <p class="_attribution-p">
    &copy; 2010&ndash;2023 JetBrains s.r.o. and Kotlin Programming Language contributors<br>Licensed under the Apache License, Version 2.0.<br>
    <a href="https://kotlinlang.org/docs/exception-handling.html" class="_attribution-link">https://kotlinlang.org/docs/exception-handling.html</a>
  </p>
</div>
